<?xml version="1.0"?>
<!-- Revolute-Revolute Manipulator -->
<robot name="planar_3dof" xmlns:xacro="http://www.ros.org/wiki/xacro">

  <!-- Constants for robot dimensions -->
  <xacro:property name="PI" value="3.1415926535897931"/>
  <xacro:property name="mass" value="1" />

  <xacro:property name="scale_dim" value="1.0" />
  <xacro:property name="base_z_displacement" value="0.051" /> 
  <xacro:property name="link_1_bb_x" value="1.0" /> 
  <xacro:property name="link_1_bb_y" value="1.0" /> 
  <xacro:property name="link_1_bb_z" value="0.58" /> 

  <xacro:property name="link_2_bb_x" value="1.82294" /> 
  <xacro:property name="link_2_bb_y" value="0.603217" /> 
  <xacro:property name="link_2_bb_z" value="0.508202" /> 

  <xacro:property name="joint1_displacement_z" value="0.585629" /> 
  
  

  <xacro:macro name="box_inertia" params="mass x y z">
    <inertia  ixx="${mass*(y*y+z*z)/12.0}" ixy = "0" ixz = "0"
              iyy="${mass*(x*x+z*z)/12.0}" iyz = "0"
              izz="${mass*(x*x+y*y)/12.0}"
    />
  </xacro:macro>

  <xacro:macro  name="cylinder_inertia" params="mass r l">
      <inertia  ixx="${mass*(3*r*r+l*l)/12}" ixy = "0" ixz = "0"
                iyy="${mass*(3*r*r+l*l)/12}" iyz = "0"
                izz="${mass*(r*r)/2}" />
  </xacro:macro >


  <xacro:include filename="$(find dh_description)/robot/dh_sim.gazebo" />

  <link name="world"/>

  <link name="link_1">
    <collision>
      <origin xyz="0 0 0" rpy="0 0 0"/>
          <geometry>
                <mesh filename="package://dh_description/meshes/dh_sim_link1.dae" scale="${scale_dim} ${scale_dim} ${scale_dim}"/>
          </geometry>
    </collision>

    <visual>
      <origin xyz="0 0 0" rpy="0 0 0"/>
          <geometry>
                <mesh filename="package://dh_description/meshes/dh_sim_link1.dae" scale="${scale_dim} ${scale_dim} ${scale_dim}"/>
          </geometry>
    </visual>

    <inertial>
      <origin xyz="0 0 0" rpy="0 0 0"/>
      <mass value="${mass}"/>
      <xacro:box_inertia mass="${mass}" x="${link_1_bb_x}" y="${link_1_bb_y}" z="${link_1_bb_z}"/>
    </inertial>
  </link>

  <joint name="fixed_world_to_base_joint" type="fixed">
    <origin xyz="0 0 ${base_z_displacement}" rpy="0 0 0"/>
    <parent link="world"/>
    <child link="link_1"/>
  </joint>


  <link name="link_2">
    <collision>
      <origin xyz="0 0 0" rpy="0 0 0"/>
          <geometry>
                <mesh filename="package://dh_description/meshes/dh_sim_link_2.dae" scale="${scale_dim} ${scale_dim} ${scale_dim}"/>
          </geometry>
    </collision>

    <visual>
      <origin xyz="0 0 0" rpy="0 0 0"/>
          <geometry>
                <mesh filename="package://dh_description/meshes/dh_sim_link_2.dae" scale="${scale_dim} ${scale_dim} ${scale_dim}"/>
          </geometry>
    </visual>

    <inertial>
      <origin xyz="0 0 0" rpy="0 0 0"/>
      <mass value="${mass}"/>
      <xacro:box_inertia mass="${mass}" x="${link_2_bb_x}" y="${link_2_bb_y}" z="${link_2_bb_z}"/>
    </inertial>
  </link> 

  <joint name="joint1" type="continuous">
    <parent link="link_1"/>
    <child link="link_2"/>
    <origin xyz="0 0 ${joint1_displacement_z}" rpy="0 0 0"/>
    <axis xyz="0 0 1"/>
  </joint>

    
  
  <transmission name="tran1">
    <type>transmission_interface/SimpleTransmission</type>
    <joint name="joint1">
      <hardwareInterface>EffortJointInterface</hardwareInterface>
    </joint>
    <actuator name="motor1">
      <hardwareInterface>EffortJointInterface</hardwareInterface>
      <mechanicalReduction>1</mechanicalReduction>
    </actuator>
  </transmission>


  
</robot>
